Workbook

Sheet DASHBOARD
B2: 🚁 QUADROTOR PROJECT — BÁM MỤC TIÊU & TRÁNH VẬT CẢN
B3: Automatic Target Following & Obstacle Avoidance in Real-Time
B5: Project Start | C5: Project End | D5: Duration | E5: Today | F5: Days Remaining | G5: Weeks Remaining
B6: 24/08/2026 | C6: 25/10/2026 | D6: 9 tuần | E6: =TODAY() -> 46257 | F6: =MAX(0, DATE(2026,10,25)-TODAY()) -> 63 | G6: =ROUNDUP(G6/7, 0)
B8: 👥 TEAM MEMBERS
B9: Member | C9: Role | D9: Tasks Assigned | E9: Tasks Completed | F9: Completion %
B10: Duy | C10: Xử lý tín hiệu & Định vị | D10: =COUNTIF(TASK_TRACKER!H:H,"*Duy*")+COUNTIF(TASK_TRACKER!H:H,"Cả nhóm") -> 18 | E10: =COUNTIFS(TASK_TRACKER!H:H,"*Duy*",TASK_TRACKER!P:P,"✅ Done")+COUNTIFS(TASK_TRACKER!H:H,"Cả nhóm",TASK_TRACKER!P:P,"✅ Done") -> 1 | F10: =IF(D10=0,0,E10/D10) -> 0.055555556
B11: Tuân | C11: Điều khiển & Dẫn đường | D11: =COUNTIF(TASK_TRACKER!H:H,"*Tuân*")+COUNTIF(TASK_TRACKER!H:H,"Cả nhóm") -> 14 | E11: =COUNTIFS(TASK_TRACKER!H:H,"*Tuân*",TASK_TRACKER!P:P,"✅ Done")+COUNTIFS(TASK_TRACKER!H:H,"Cả nhóm",TASK_TRACKER!P:P,"✅ Done") -> 0 | F11: =IF(D11=0,0,E11/D11) -> 0
B12: Việt Anh | C12: Lập trình nhúng & Triển khai | D12: =COUNTIF(TASK_TRACKER!H:H,"*Việt Anh*")+COUNTIF(TASK_TRACKER!H:H,"Cả nhóm") -> 14 | E12: =COUNTIFS(TASK_TRACKER!H:H,"*Việt Anh*",TASK_TRACKER!P:P,"✅ Done")+COUNTIFS(TASK_TRACKER!H:H,"Cả nhóm",TASK_TRACKER!P:P,"✅ Done") -> 0 | F12: =IF(D12=0,0,E12/D12) -> 0
B14: 🎯 MILESTONE COUNTDOWN
B15: Milestone | C15: Target Date | D15: Days Left | E15: KPI | F15: Status
B16: MS1: Simulink APF hoàn chỉnh | C16: 46264 | D16: =MAX(0, C16-TODAY()) -> 7 | E16: Tracking error < 0.3m (sim) | F16: ⬜ Pending
B17: MS2: Vision Pipeline 30 FPS | C17: 46271 | D17: =MAX(0, C17-TODAY()) -> 14 | E17: mAP > 0.8, 3D error < 0.5m | F17: ⬜ Pending
B18: MS3: SITL Follow-Me + Obstacle | C18: 46285 | D18: =MAX(0, C18-TODAY()) -> 28 | E18: Bám ≥ 60s, né ≥ 3 vật cản | F18: ⬜ Pending
B19: MS4: Hardware Ready | C19: 46292 | D19: =MAX(0, C19-TODAY()) -> 35 | E19: Telemetry ổn định ≥ 30 phút | F19: ⬜ Pending
B20: MS5: Real Flight Follow | C20: 46299 | D20: =MAX(0, C20-TODAY()) -> 42 | E20: Bám ≥ 30s, error < 1.5m | F20: ⬜ Pending
B21: MS6: Full System (Obstacle) | C21: 46306 | D21: =MAX(0, C21-TODAY()) -> 49 | E21: Min clearance > 0.8m | F21: ⬜ Pending
B22: MS7: Final Report | C22: 46320 | D22: =MAX(0, C22-TODAY()) -> 63 | E22: Báo cáo + video hoàn chỉnh | F22: ⬜ Pending
B24: 📊 OVERALL PROGRESS
B25: Total Tasks | C25: Completed | D25: In Progress | E25: Blocked | F25: Overall %
B26: =COUNTA(TASK_TRACKER!B4:B100) -> 32 | C26: =COUNTIF(TASK_TRACKER!P4:P100,"✅ Done") -> 1 | D26: =COUNTIF(TASK_TRACKER!P4:P100,"🔵 In Progress") -> 0 | E26: =COUNTIF(TASK_TRACKER!P4:P100,"🔴 Blocked") -> 0 | F26: =IF(B26=0,0,C26/B26) -> 0.03125
B28: 📈 PHASE PROGRESS
B29: Phase | C29: Total Tasks | D29: Done | E29: Progress % | F29: Weeks
B30: GĐ1: Simulation & APF | C30: =COUNTIF(TASK_TRACKER!C4:C100,"GĐ1*") -> 8 | D30: =COUNTIFS(TASK_TRACKER!C4:C100,"GĐ1*",TASK_TRACKER!P4:P100,"✅ Done") -> 1 | E30: =IF(C30=0,0,D30/C30) -> 0.125 | F30: W1-W2
B31: GĐ2: Tracking & Follow | C31: =COUNTIF(TASK_TRACKER!C4:C100,"GĐ2*") -> 8 | D31: =COUNTIFS(TASK_TRACKER!C4:C100,"GĐ2*",TASK_TRACKER!P4:P100,"✅ Done") -> 0 | E31: =IF(C31=0,0,D31/C31) -> 0 | F31: W3-W4
B32: GĐ3: Hardware & Bench Test | C32: =COUNTIF(TASK_TRACKER!C4:C100,"GĐ3*") -> 8 | D32: =COUNTIFS(TASK_TRACKER!C4:C100,"GĐ3*",TASK_TRACKER!P4:P100,"✅ Done") -> 0 | E32: =IF(C32=0,0,D32/C32) -> 0 | F32: W5-W6
B33: GĐ4: Thực nghiệm & Báo cáo | C33: =COUNTIF(TASK_TRACKER!C4:C100,"GĐ4*") -> 8 | D33: =COUNTIFS(TASK_TRACKER!C4:C100,"GĐ4*",TASK_TRACKER!P4:P100,"✅ Done") -> 0 | E33: =IF(C33=0,0,D33/C33) -> 0 | F33: W7-W9
B35: ⚠️ ALERTS & NOTES
B36: ⏰ Overdue tasks:
B39: 🔴 Blocked tasks:
B40: =COUNTIF(TASK_TRACKER!P4:P100,"🔴 Blocked") & " task(s) blocked" -> 0 task(s) blocked
B42: 📋 Notes: Weekly review mỗi thứ 6. Update status trước khi họp.

Sheet TASK_TRACKER
A1: 📋 TASK TRACKER — Quadrotor Follow-Me & Obstacle Avoidance Project
A2: Start: 24/08/2026 | End: 25/10/2026 | Team: Duy · Tuân · Việt Anh
A3: No. | B3: Task ID | C3: Giai đoạn | D3: Week | E3: Module | F3: Tên nhiệm vụ | G3: Mô tả chi tiết | H3: Owner | I3: Reviewer | J3: Priority | K3: Predecessor | L3: Planned Start | M3: Planned End | N3: Actual Start | O3: Actual End | P3: Status | Q3: % Complete | R3: Countdown (days) | S3: Effort (hours) | T3: Deliverable | U3: Acceptance Criteria | V3: Notes / Blockers
A4: 1 | B4: GĐ1-T01 | C4: GĐ1: Simulation & APF | D4: W1 | E4: M1 | F4: Xây dựng mô hình động học 6DOF UAV trên Simulink | G4: Mô hình input: lực/moment, output: pose (x,y,z,φ,θ,ψ). Bao gồm mô hình cánh quạt, trọng lực, khí động. | H4: Tuân | I4: Duy | J4: 🔴 Critical | K4: — | L4: 46258 | M4: 46261 | P4: ⬜ Not Started | Q4: 0 | R4: =IF(P4="✅ Done","—",MAX(0,M4-TODAY())) -> 4 | S4: 16 | T4: File .slx mô hình UAV | U4: Mô hình chạy ổn định, output đúng physical unit
A5: 2 | B5: GĐ1-T02 | C5: GĐ1: Simulation & APF | D5: W1 | E5: M8 | F5: Lập trình hàm APF: lực hút, lực đẩy, Modified APF | G5: Triển khai Attractive Potential, Repulsive Potential, xử lý GNRON (Goal Non-Reachable with Obstacles Nearby), lực xoay chống Local Minima. | H5: Tuân | I5: Duy | J5: 🔴 Critical | K5: GĐ1-T01 | L5: 46260 | M5: 46264 | P5: ⬜ Not Started | Q5: 0 | R5: =IF(P5="✅ Done","—",MAX(0,M5-TODAY())) -> 7 | S5: 20 | T5: Module APF (.m/.slx) | U5: APF hội tụ với ≥ 5 cấu hình vật cản khác nhau
A6: 3 | B6: GĐ1-T03 | C6: GĐ1: Simulation & APF | D6: W1 | E6: M2 | F6: Nghiên cứu & chuẩn bị pipeline YOLO detection | G6: Survey YOLO versions (v8/v11), chọn model phù hợp cho embedded. Chuẩn bị dataset, test trên PC. | H6: Duy | I6: Tuân | J6: 🟡 High | K6: — | L6: 46258 | M6: 46262 | P6: ⬜ Not Started | Q6: 0 | R6: =IF(P6="✅ Done","—",MAX(0,M6-TODAY())) -> 5 | S6: 12 | T6: Report chọn model + benchmark | U6: Model chạy được trên PC, mAP > 0.7 trên test set
A7: 4 | B7: GĐ1-T04 | C7: GĐ1: Simulation & APF | D7: W1 | E7: M1 | F7: Cài đặt Ubuntu + ROS 2 Humble + PX4-Autopilot | G7: Setup dual-boot/VM, cài ROS 2 Humble, PX4 SITL, Gazebo Garden. Đảm bảo build thành công. | H7: Duy | I7: Tuân | J7: 🔴 Critical | K7: — | L7: 46258 | M7: 46261 | P7: ✅ Done | Q7: 0 | R7: =IF(P7="✅ Done","—",MAX(0,M7-TODAY())) -> — | S7: 10 | T7: Screenshot build thành công | U7: PX4 SITL + Gazebo chạy được, ROS 2 topic nhận được
A8: 5 | B8: GĐ1-T05 | C8: GĐ1: Simulation & APF | D8: W2 | E8: M8 | F8: Quét bộ thông số APF (k_att, k_rep, d0) trên Simulink | G8: Chạy Monte Carlo/grid search trên các bộ thông số. Tìm bộ tối ưu cho nhiều kịch bản vật cản. | H8: Tuân | I8: Duy | J8: 🟡 High | K8: GĐ1-T02 | L8: 46265 | M8: 46268 | P8: ⬜ Not Started | Q8: 0 | R8: =IF(P8="✅ Done","—",MAX(0,M8-TODAY())) -> 11 | S8: 14 | T8: Bảng thông số tối ưu + đồ thị quỹ đạo | U8: Tracking error < 0.3m trên simulation, quỹ đạo mượt
A9: 6 | B9: GĐ1-T06 | C9: GĐ1: Simulation & APF | D9: W2 | E9: M2/M3 | F9: Tích hợp YOLO + ByteTrack, tính toạ độ 3D từ depth | G9: Kết hợp YOLO detection với ByteTrack tracker. Sử dụng depth camera để tính toạ độ 3D trong Local Frame. | H9: Duy | I9: Việt Anh | J9: 🔴 Critical | K9: GĐ1-T03 | L9: 46265 | M9: 46270 | P9: ⬜ Not Started | Q9: 0 | R9: =IF(P9="✅ Done","—",MAX(0,M9-TODAY())) -> 13 | S9: 18 | T9: Python module Vision pipeline | U9: Tracking liên tục ≥ 30 FPS, 3D error < 0.5m trong phòng
A10: 7 | B10: GĐ1-T07 | C10: GĐ1: Simulation & APF | D10: W1 | E10: M1/M9 | F10: Thiết lập Offboard control: takeoff, land, waypoint | G10: Xây dựng ROS 2 node giao tiếp PX4 qua uXRCE-DDS. Thực hiện takeoff, land, waypoint tracking trong Gazebo. | H10: Việt Anh | I10: Duy | J10: 🔴 Critical | K10: GĐ1-T04 | L10: 46265 | M10: 46270 | P10: ⬜ Not Started | Q10: 0 | R10: =IF(P10="✅ Done","—",MAX(0,M10-TODAY())) -> 13 | S10: 16 | T10: ROS 2 package offboard_control | U10: UAV takeoff → waypoint → land thành công 100% trong SITL
A11: 8 | B11: GĐ1-T08 | C11: GĐ1: Simulation & APF | D11: W2 | E11: M1 | F11: Xác định hệ quy chiếu & interface giữa các module | G11: Thống nhất frame conventions (NED/ENU), message types, topic names giữa Vision → Control → PX4. | H11: Cả nhóm | I11: — | J11: 🟡 High | K11: GĐ1-T04 | L11: 46267 | M11: 46268 | P11: ⬜ Not Started | Q11: 0 | R11: =IF(P11="✅ Done","—",MAX(0,M11-TODAY())) -> 11 | S11: 6 | T11: Document interface specification | U11: Tài liệu rõ ràng, cả nhóm thống nhất
A12: 9 | B12: GĐ2-T01 | C12: GĐ2: Tracking & Follow | D12: W3 | E12: M4/M5 | F12: Thiết kế EKF ước lượng vận tốc mục tiêu | G12: Extended Kalman Filter: state = [x, y, z, vx, vy, vz], measurement từ Vision pipeline. Tune Q, R matrices. | H12: Duy | I12: Tuân | J12: 🔴 Critical | K12: GĐ1-T06 | L12: 46272 | M12: 46276 | P12: ⬜ Not Started | Q12: 0 | R12: =IF(P12="✅ Done","—",MAX(0,M12-TODAY())) -> 19 | S12: 18 | T12: EKF module (Python/C++) | U12: Velocity estimate error < 0.3 m/s trên dữ liệu mô phỏng
A13: 10 | B13: GĐ2-T02 | C13: GĐ2: Tracking & Follow | D13: W3 | E13: M5 | F13: Lập trình Dead Reckoning khi mất dấu mục tiêu | G13: Khi camera mất dấu (1-2s), sử dụng EKF prediction để duy trì ước lượng vị trí mục tiêu. | H13: Duy | I13: Tuân | J13: 🟡 High | K13: GĐ2-T01 | L13: 46275 | M13: 46278 | P13: ⬜ Not Started | Q13: 0 | R13: =IF(P13="✅ Done","—",MAX(0,M13-TODAY())) -> 21 | S13: 10 | T13: Dead Reckoning module | U13: Dự đoán đúng hướng đi khi ngắt frame 1-2s
A14: 11 | B14: GĐ2-T03 | C14: GĐ2: Tracking & Follow | D14: W3 | E14: M6 | F14: Xây dựng quy luật bám mục tiêu ảo | G14: Thiết kế guidance law: UAV giữ khoảng cách d_follow phía sau mục tiêu, tự điều chỉnh heading. | H14: Tuân | I14: Duy | J14: 🔴 Critical | K14: GĐ1-T05 | L14: 46272 | M14: 46277 | P14: ⬜ Not Started | Q14: 0 | R14: =IF(P14="✅ Done","—",MAX(0,M14-TODAY())) -> 20 | S14: 16 | T14: Follow guidance module | U14: UAV giữ khoảng cách ổn định ±2m trong SITL
A15: 12 | B15: GĐ2-T04 | C15: GĐ2: Tracking & Follow | D15: W3 | E15: M1 | F15: Tích hợp Vision node vào ROS 2, publish topic | G15: Đóng gói Vision pipeline thành ROS 2 node, publish TargetState message lên topic. | H15: Việt Anh | I15: Duy | J15: 🟡 High | K15: GĐ1-T06, GĐ1-T07 | L15: 46272 | M15: 46276 | P15: ⬜ Not Started | Q15: 0 | R15: =IF(P15="✅ Done","—",MAX(0,M15-TODAY())) -> 19 | S15: 12 | T15: ROS 2 vision node package | U15: Topic publish ổn định ≥ 30 Hz
... A35: 32 | B35: GĐ4-T08 | C35: GĐ4: Thực nghiệm & Báo cáo | D35: W9 | E35: — | F35: Buffer: Bay bổ sung / fix bugs / cải thiện | G35: Thời gian dự phòng cho các vấn đề phát sinh. Bay thêm nếu cần data. | H35: Cả nhóm | I35: — | J35: 🟢 Normal | K35: — | L35: 46314 | M35: 46320 | P35: ⬜ Not Started | Q35: 0 | R35: =IF(P35="✅ Done","—",MAX(0,M35-TODAY())) -> 63 | S35: 12 | T35: Updated results nếu có | U35: —

Sheet GANTT_VIEW
A1: 📅 GANTT CHART — 9-Week Timeline
A2: No. | B2: Task ID | C2: Task Name | D2: Owner | E2: W1 | L2: W2 | S2: W3 | Z2: W4 | AG2: W5 | AN2: W6 | AU2: W7 | BB2: W8 | BI2: W9
E3: 24 | F3: 25 | G3: 26 | H3: 27 | I3: 28 | J3: 29 | K3: 30 | L3: 31 | M3: 1 | N3: 2 | O3: 3 | P3: 4 | Q3: 5 | R3: 6 | S3: 7 | T3: 8 | U3: 9 | V3: 10 | W3: 11 | X3: 12 | Y3: 13 | Z3: 14 | AA3: 15 | AB3: 16 | AC3: 17 | AD3: 18 | AE3: 19 | AF3: 20 | AG3: 21 | AH3: 22 | AI3: 23 | AJ3: 24 | AK3: 25 | AL3: 26 | AM3: 27 | AN3: 28 | AO3: 29 | AP3: 30 | AQ3: 1 | AR3: 2 | AS3: 3 | AT3: 4 | AU3: 5 | AV3: 6 | AW3: 7 | AX3: 8 | AY3: 9 | AZ3: 10 | BA3: 11 | BB3: 12 | BC3: 13 | BD3: 14 | BE3: 15 | BF3: 16 | BG3: 17 | BH3: 18 | BI3: 19 | BJ3: 20 | BK3: 21 | BL3: 22 | BM3: 23 | BN3: 24 | BO3: 25
A4: 1 | B4: GĐ1-T01 | C4: Xây dựng mô hình động học 6DOF UAV trên Simulink | D4: Tuân
A5: 2 | B5: GĐ1-T02 | C5: Lập trình hàm APF: lực hút, lực đẩy, Modified APF | D5: Tuân
A6: 3 | B6: GĐ1-T03 | C6: Nghiên cứu & chuẩn bị pipeline YOLO detection | D6: Duy
A7: 4 | B7: GĐ1-T04 | C7: Cài đặt Ubuntu + ROS 2 Humble + PX4-Autopilot | D7: Việt Anh
A8: 5 | B8: GĐ1-T05 | C8: Quét bộ thông số APF (k_att, k_rep, d0) trên Simulink | D8: Tuân
A9: 6 | B9: GĐ1-T06 | C9: Tích hợp YOLO + ByteTrack, tính toạ độ 3D từ depth | D9: Duy
A10: 7 | B10: GĐ1-T07 | C10: Thiết lập Offboard control: takeoff, land, waypoint | D10: Việt Anh
A11: 8 | B11: GĐ1-T08 | C11: Xác định hệ quy chiếu & interface giữa các module | D11: Cả nhóm
A12: 9 | B12: GĐ2-T01 | C12: Thiết kế EKF ước lượng vận tốc mục tiêu | D12: Duy
A13: 10 | B13: GĐ2-T02 | C13: Lập trình Dead Reckoning khi mất dấu mục tiêu | D13: Duy
A14: 11 | B14: GĐ2-T03 | C14: Xây dựng quy luật bám mục tiêu ảo | D14: Tuân
A15: 12 | B15: GĐ2-T04 | C15: Tích hợp Vision node vào ROS 2, publish topic | D15: Việt Anh
... A18: 15 | B18: GĐ2-T07 | C18: Xây dựng State Machine (SEARCH/FOLLOW/AVOID/HOLD) | D18: Việt Anh
A19: 16 | B19: GĐ2-T08 | C19: ★ MILESTONE 1: Test tích hợp toàn hệ thống trên SITL | D19: Cả nhóm | AF19: ◆
A20: 17 | B20: GĐ3-T01 | C20: Lắp ráp Companion Computer + Camera lên kit X500 | D20: Cả nhóm
A21: 18 | B21: GĐ3-T02 | C21: Thiết lập UART/USB giữa máy tính nhúng và PX4 | D21: Việt Anh
A22: 19 | B22: GĐ3-T03 | C22: Tối ưu YOLO → TensorRT/ONNX cho máy tính nhúng | D22: Duy
A23: 20 | B23: GĐ3-T04 | C23: Fine-tune APF + EKF parameters trên SITL | D23: Tuân
A24: 21 | B24: GĐ3-T05 | C24: Test camera + Vision pipeline trên phần cứng | D24: Duy
A25: 22 | B25: GĐ3-T06 | C25: Dry Run: test motor response (không cánh quạt) | D25: Việt Anh
A26: 23 | B26: GĐ3-T07 | C26: Calibrate thuật toán APF/EKF trên phần cứng thực | D26: Tuân
A27: 24 | B27: GĐ3-T08 | C27: Bay bãi trống: bám mục tiêu động (chưa có vật cản) | D27: Cả nhóm
A28: 25 | B28: GĐ4-T01 | C28: Setup bãi thử nghiệm có vật cản mềm/an toàn | D28: Việt Anh
A29: 26 | B29: GĐ4-T02 | C29: Bay thực với vật cản: APF + EKF full system | D29: Cả nhóm
A30: 27 | B30: GĐ4-T03 | C30: Test kịch bản target lost & re-acquisition | D30: Duy
A31: 28 | B31: GĐ4-T04 | C31: Trích xuất & phân tích log (PX4 ulog + ROS 2 bag) | D31: Duy
... A35: 32 | B35: GĐ4-T08 | C35: Buffer: Bay bổ sung / fix bugs / cải thiện | D35: Cả nhóm
A38: Legend:
B39: ██ | C39: GĐ1: Simulation & APF
B40: ██ | C40: GĐ2: Tracking & Follow
B41: ██ | C41: GĐ3: Hardware & Bench
B42: ██ | C42: GĐ4: Thực nghiệm & Báo cáo
B43: ██ | C43: ◆ = Milestone

Sheet RISK_LOG
A1: ⚠️ RISK REGISTER — Quadrotor Project
A2: Proactive risk management — Required for hardware flight testing
A3: Risk ID | B3: Mô tả rủi ro | C3: Probability | D3: Impact | E3: Risk Score | F3: Mitigation Plan | G3: Contingency Plan | H3: Owner | I3: Status | J3: Related Tasks | K3: Last Updated
A4: R01 | B4: Camera depth không chính xác ngoài trời do ánh sáng mạnh/IR interference | C4: High | D4: High | E4: 🔴 9 (Extreme) | F4: Mitigation: Sử dụng stereo matching thay vì structured light depth. Test outdoor trước W5. | G4: Fallback: GPS-only relative positioning | H4: Duy | I4: Open | J4: GĐ1-T06, GĐ3-T05
A5: R02 | B5: TensorRT conversion fail hoặc FPS quá thấp trên máy tính nhúng | C5: Medium | D5: High | E5: 🟡 6 (High) | F5: Mitigation: Chuẩn bị model nhẹ hơn (YOLOv8n). Test conversion sớm từ W3. | G5: Fallback: Chạy ONNX Runtime thay TensorRT | H5: Duy | I5: Open | J5: GĐ3-T03
A6: R03 | B6: Giao tiếp UART/USB giữa companion computer và PX4 không ổn định | C6: Medium | D6: Critical | E6: 🟡 8 (High) | F6: Mitigation: Test kỹ baudrate, cable quality. Có backup cable. | G6: Fallback: Sử dụng Ethernet/WiFi bridge | H6: Việt Anh | I6: Open | J6: GĐ3-T02
A7: R04 | B7: GPS drift gây sai lệch vị trí khi bay outdoor | C7: High | D7: Medium | E7: 🟡 6 (High) | F7: Mitigation: Sử dụng relative position (camera-based) thay vì absolute GPS. | G7: Fallback: Bay trong khu vực có RTK GPS | H7: Duy | I7: Open | J7: GĐ3-T08
A8: R05 | B8: Wind disturbance gây mất ổn định khi bay thực | C8: Medium | D8: High | E8: 🟡 6 (High) | F8: Mitigation: Chọn ngày gió nhẹ < 3 m/s. Tune PID cho wind rejection. | G8: Fallback: Bay indoor trong nhà kho/gym lớn | H8: Tuân | I8: Open | J8: GĐ3-T08, GĐ4-T02
A9: R06 | B9: Local Minima trong APF - UAV bị kẹt giữa các vật cản | C9: Medium | D9: Medium | E9: 🟠 4 (Medium) | F9: Mitigation: Modified APF với lực xoay + random perturbation. | G9: Fallback: Switch sang simple waypoint bypass | H9: Tuân | I9: Open | J9: GĐ2-T06
A10: R07 | B10: Thời gian 9 tuần không đủ để hoàn thành toàn bộ scope | C10: High | D10: High | E10: 🔴 9 (Extreme) | F10: Mitigation: Prioritize MVP (follow without NN prediction). Weekly review cắt scope sớm. | G10: Fallback: Demo SITL nếu không kịp bay thật | H10: Cả nhóm | I10: Open | J10: GĐ4-T07
A11: R08 | B11: Phần cứng hư hỏng khi bay test (crash, ESC cháy...) | C11: Medium | D11: Critical | E11: 🟡 8 (High) | F11: Mitigation: Dry run kỹ. Bay thấp (< 3m) ban đầu. Kill switch luôn sẵn sàng. | G11: Fallback: Có spare parts (ESC, propeller). Budget repair time vào W9. | H11: Việt Anh | I11: Open | J11: GĐ3-T06, GĐ4-T02
A14: 📊 Risk Matrix Reference
B15: Low Impact (1) | C15: Medium (2) | D15: High (3) | E15: Critical (4)
A16: High (3) | B16: 3 | C16: 6 | D16: 9 | E16: 12
A17: Medium (2) | B17: 2 | C17: 4 | D17: 6 | E17: 8
A18: Low (1) | B18: 1 | C18: 2 | D18: 3 | E18: 4

Sheet WEEKLY_REPORT
A1: 📝 WEEKLY REPORT TEMPLATE
A2: Fill in before each Friday review meeting
B4: 📅 WEEK 1 (24/08 — 30/08/2026)
B5: Review Date: | C5: 46262 | E5: Attendees: | F5: Duy, Tuân, Việt Anh
B6: ✅ Completed This Week | E6: 🚧 Blockers & Issues
B7: 1. | E7: 1.
B8: 2. | E8: 2.
B9: 3. | E9: 3.
B10: 4. | E10: 4.
B11: 5. | E11: 5.
B12: 📋 Planned for Next Week | E12: 💡 Decisions Made
B13: 1. | E13: 1.
B14: 2. | E14: 2.
B15: 3. | E15: 3.
B16: 4. | E16: 4.
B17: 5. | E17: 5.
B18: 🎯 Action Items
C19: Action | D19: Owner | F19: Deadline
B20: 1.
B21: 2.
B22: 3.
B25: 📅 WEEK 2 (31/08 — 06/09/2026)
B26: Review Date: | C26: 46269 | E26: Attendees: | F26: Duy, Tuân, Việt Anh
B27: ✅ Completed This Week | E27: 🚧 Blockers & Issues
B28: 1. | E28: 1.
B29: 2. | E29: 2.
B30: 3. | E30: 3.
B31: 4. | E31: 4.
B32: 5. | E32: 5.
B33: 📋 Planned for Next Week | E33: 💡 Decisions Made
B34: 1. | E34: 1.
B35: 2. | E35: 2.
B36: 3. | E36: 3.
B37: 4. | E37: 4.
B38: 5. | E38: 5.
B39: 🎯 Action Items
C40: Action | D40: Owner | F40: Deadline
B41: 1.
B42: 2.
B43: 3.
...
